Workbook
Name O: 'Actual Expenses'!$O$539

Sheet Cover Page
C3: Budget & Forecast Model
C7: Get 10% OFF our course using coupon code EMAIL10
C9: Get our Complete Finance & Valuation Course
C11: Go to Sheet 1 -> here
C13: Made by Career Principles Ltd.
C15: Note
C16: All content is copyright material of Career Principles Ltd.
C17: This Excel model may not be reproduced or distributed by any means, including printing, screencapturing, or any other method without the prior permission of the publisher.

Sheet Actual Expenses
B2: Start Date | C2: 45536
B4: Actual Operating Expenses
B5: Account # | C5: Department | D5: Description | E5: =C2 -> 45536 | F5: =EDATE(E5,1) -> 45566 | G5: =EDATE(F5,1) -> 45597 | H5: =EDATE(G5,1) -> 45627
B6: 11256 | C6: Marketing | D6: Paid Ads | E6: 22992 | F6: 24001 | G6: 26558 | H6: 25446
B7: 11257 | C7: Marketing | D7: Infuencers | E7: 53326 | F7: 54223 | G7: 51000 | H7: 50000
B8: 11259 | C8: Engineering | D8: Consulting | E8: 35888 | F8: 36880 | G8: 37995 | H8: 40000
B9: 11260 | C9: Engineering | D9: Travel | E9: 87942 | F9: 85224 | G9: 82469 | H9: 81005
B10: 11263 | C10: Support | D10: Software | E10: 92622 | F10: 90005 | G10: 87556 | H10: 84522
B11: 11264 | C11: Support | D11: Call Center | E11: 27416 | F11: 26554 | G11: 24330 | H11: 22338
B12: 11267 | C12: HR | D12: Recruiting Events | E12: 41696 | F12: 41696 | G12: 42558 | H12: 45448
B13: 11268 | C13: HR | D13: Meetups | E13: 60285 | F13: 61225 | G13: 68994 | H13: 72410

Sheet Forecast
B2: Live Case | E2: Actuals | I2: Forecast
B3: =B15 -> Account # | C3: =C15 -> Department | D3: =D15 -> Description | E3: =E15 -> 45536 | F3: =F15 -> 45566 | G3: =G15 -> 45597 | H3: =H15 -> 45627 | I3: =I15 -> 45658 | ... T3: =T15 -> 45992
B4: =B16 -> 11256 | C4: =C16 -> Marketing | D4: =D16 -> Paid Ads | E4: =E16 -> 22992 | F4: =F16 -> 24001 | G4: =G16 -> 26558 | H4: =H16 -> 25446 | I4: =CHOOSE('Income Statement'!$C$2,Forecast!I27,Forecast!I16,Forecast!I38) -> 34917.689 | J4: =CHOOSE('Income Statement'!$C$2,Forecast!J27,Forecast!J16,Forecast!J38) -> 34999.372 | K4: =CHOOSE('Income Statement'!$C$2,Forecast!K27,Forecast!K16,Forecast!K38) -> 37128.286 | L4: =CHOOSE('Income Statement'!$C$2,Forecast!L27,Forecast!L16,Forecast!L38) -> 37051.862 | M4: =CHOOSE('Income Statement'!$C$2,Forecast!M27,Forecast!M16,Forecast!M38) -> 39131.751 | N4: =CHOOSE('Income Statement'!$C$2,Forecast!N27,Forecast!N16,Forecast!N38) -> 39145.235 | O4: =CHOOSE('Income Statement'!$C$2,Forecast!O27,Forecast!O16,Forecast!O38) -> 41173.846 | P4: =CHOOSE('Income Statement'!$C$2,Forecast!P27,Forecast!P16,Forecast!P38) -> 41188.471 | ... T4: =CHOOSE('Income Statement'!$C$2,Forecast!T27,Forecast!T16,Forecast!T38) -> 45261.932
B5: =B17 -> 11257 | C5: =C17 -> Marketing | D5: =D17 -> Infuencers | E5: =E17 -> 53326 | F5: =F17 -> 54223 | G5: =G17 -> 51000 | H5: =H17 -> 50000 | I5: =CHOOSE('Income Statement'!$C$2,Forecast!I28,Forecast!I17,Forecast!I39) -> 34200.981 | J5: =CHOOSE('Income Statement'!$C$2,Forecast!J28,Forecast!J17,Forecast!J39) -> 33310.176 | K5: =CHOOSE('Income Statement'!$C$2,Forecast!K28,Forecast!K17,Forecast!K39) -> 32090.815 | L5: =CHOOSE('Income Statement'!$C$2,Forecast!L28,Forecast!L17,Forecast!L39) -> 31213.974 | M5: =CHOOSE('Income Statement'!$C$2,Forecast!M28,Forecast!M17,Forecast!M39) -> 30010.158 | N5: =CHOOSE('Income Statement'!$C$2,Forecast!N28,Forecast!N17,Forecast!N39) -> 29161.646 | O5: =CHOOSE('Income Statement'!$C$2,Forecast!O28,Forecast!O17,Forecast!O39) -> 27790.839 | P5: =CHOOSE('Income Statement'!$C$2,Forecast!P28,Forecast!P17,Forecast!P39) -> 26969.094 | ... T5: =CHOOSE('Income Statement'!$C$2,Forecast!T28,Forecast!T17,Forecast!T39) -> 22623.486
B6: =B18 -> 11259 | C6: =C18 -> Engineering | D6: =D18 -> Consulting | E6: =E18 -> 35888 | F6: =F18 -> 36880 | G6: =G18 -> 37995 | H6: =H18 -> 40000 | I6: =CHOOSE('Income Statement'!$C$2,Forecast!I29,Forecast!I18,Forecast!I40) -> 28828.78 | J6: =CHOOSE('Income Statement'!$C$2,Forecast!J29,Forecast!J18,Forecast!J40) -> 29829.57 | K6: =CHOOSE('Income Statement'!$C$2,Forecast!K29,Forecast!K18,Forecast!K40) -> 30825.318 | L6: =CHOOSE('Income Statement'!$C$2,Forecast!L29,Forecast!L18,Forecast!L40) -> 31789.738 | M6: =CHOOSE('Income Statement'!$C$2,Forecast!M29,Forecast!M18,Forecast!M40) -> 32770.197 | N6: =CHOOSE('Income Statement'!$C$2,Forecast!N29,Forecast!N18,Forecast!N40) -> 33750.718 | O6: =CHOOSE('Income Statement'!$C$2,Forecast!O29,Forecast!O18,Forecast!O40) -> 34731.303 | P6: =CHOOSE('Income Statement'!$C$2,Forecast!P29,Forecast!P18,Forecast!P40) -> 35711.936 | ... T6: =CHOOSE('Income Statement'!$C$2,Forecast!T29,Forecast!T18,Forecast!T40) -> 39634.614
B7: =B19 -> 11260 | C7: =C19 -> Engineering | D7: =D19 -> Travel | E7: =E19 -> 87942 | F7: =F19 -> 85224 | G7: =G19 -> 82469 | H7: =H19 -> 81005 | I7: =CHOOSE('Income Statement'!$C$2,Forecast!I30,Forecast!I19,Forecast!I41) -> 54899.524 | J7: =CHOOSE('Income Statement'!$C$2,Forecast!J30,Forecast!J19,Forecast!J41) -> 53324.63 | K7: =CHOOSE('Income Statement'!$C$2,Forecast!K30,Forecast!K19,Forecast!K41) -> 51738.726 | L7: =CHOOSE('Income Statement'!$C$2,Forecast!L30,Forecast!L19,Forecast!L41) -> 50128.337 | M7: =CHOOSE('Income Statement'!$C$2,Forecast!M30,Forecast!M19,Forecast!M41) -> 48532.325 | N7: =CHOOSE('Income Statement'!$C$2,Forecast!N30,Forecast!N19,Forecast!N41) -> 46935.402 | O7: =CHOOSE('Income Statement'!$C$2,Forecast!O30,Forecast!O19,Forecast!O41) -> 45337.88 | P7: =CHOOSE('Income Statement'!$C$2,Forecast!P30,Forecast!P19,Forecast!P41) -> 43736.51 | ... T7: =CHOOSE('Income Statement'!$C$2,Forecast!T30,Forecast!T19,Forecast!T41) -> 37341.371
B8: =B20 -> 11263 | C8: =C20 -> Support | D8: =D20 -> Software | E8: =E20 -> 92622 | F8: =F20 -> 90005 | G8: =G20 -> 87556 | H8: =H20 -> 84522 | I8: =CHOOSE('Income Statement'!$C$2,Forecast!I31,Forecast!I20,Forecast!I42) -> 57341.814 | J8: =CHOOSE('Income Statement'!$C$2,Forecast!J31,Forecast!J20,Forecast!J42) -> 55444.485 | K8: =CHOOSE('Income Statement'!$C$2,Forecast!K31,Forecast!K20,Forecast!K42) -> 53538.415 | L8: =CHOOSE('Income Statement'!$C$2,Forecast!L31,Forecast!L20,Forecast!L42) -> 51654.742 | M8: =CHOOSE('Income Statement'!$C$2,Forecast!M31,Forecast!M20,Forecast!M42) -> 49760.338 | N8: =CHOOSE('Income Statement'!$C$2,Forecast!N31,Forecast!N20,Forecast!N42) -> 47787.432 | O8: =CHOOSE('Income Statement'!$C$2,Forecast!O31,Forecast!O20,Forecast!O42) -> 45936.576 | P8: =CHOOSE('Income Statement'!$C$2,Forecast!P31,Forecast!P20,Forecast!P42) -> 44068.577 | ... T8: =CHOOSE('Income Statement'!$C$2,Forecast!T31,Forecast!T20,Forecast!T42) -> 36391.145
B9: =B21 -> 11264 | C9: =C21 -> Support | D9: =D21 -> Call Center | E9: =E21 -> 27416 | F9: =F21 -> 26554 | G9: =G21 -> 24330 | H9: =H21 -> 22338 | I9: =CHOOSE('Income Statement'!$C$2,Forecast!I32,Forecast!I21,Forecast!I43) -> 14549.274 | J9: =CHOOSE('Income Statement'!$C$2,Forecast!J32,Forecast!J21,Forecast!J43) -> 13276.457 | K9: =CHOOSE('Income Statement'!$C$2,Forecast!K32,Forecast!K21,Forecast!K43) -> 11997.136 | L9: =CHOOSE('Income Statement'!$C$2,Forecast!L32,Forecast!L21,Forecast!L43) -> 10778.931 | M9: =CHOOSE('Income Statement'!$C$2,Forecast!M32,Forecast!M21,Forecast!M43) -> 9537.5757 | N9: =CHOOSE('Income Statement'!$C$2,Forecast!N32,Forecast!N21,Forecast!N43) -> 8021.7835 | O9: =CHOOSE('Income Statement'!$C$2,Forecast!O32,Forecast!O21,Forecast!O43) -> 7164.9997 | P9: =CHOOSE('Income Statement'!$C$2,Forecast!P32,Forecast!P21,Forecast!P43) -> 5789.8934 | ... T9: =CHOOSE('Income Statement'!$C$2,Forecast!T32,Forecast!T21,Forecast!T43) -> 578.13463
B10: =B22 -> 11267 | C10: =C22 -> HR | D10: =D22 -> Recruiting Events | E10: =E22 -> 41696 | F10: =F22 -> 41696 | G10: =G22 -> 42558 | H10: =H22 -> 45448 | I10: =CHOOSE('Income Statement'!$C$2,Forecast!I33,Forecast!I22,Forecast!I44) -> 32379.863 | J10: =CHOOSE('Income Statement'!$C$2,Forecast!J33,Forecast!J22,Forecast!J44) -> 33393.247 | K10: =CHOOSE('Income Statement'!$C$2,Forecast!K33,Forecast!K22,Forecast!K44) -> 34405.12 | L10: =CHOOSE('Income Statement'!$C$2,Forecast!L33,Forecast!L22,Forecast!L44) -> 35316.63 | M10: =CHOOSE('Income Statement'!$C$2,Forecast!M33,Forecast!M22,Forecast!M44) -> 36277.04 | N10: =CHOOSE('Income Statement'!$C$2,Forecast!N33,Forecast!N22,Forecast!N44) -> 37237.62 | O10: =CHOOSE('Income Statement'!$C$2,Forecast!O33,Forecast!O22,Forecast!O44) -> 38198.382 | P10: =CHOOSE('Income Statement'!$C$2,Forecast!P33,Forecast!P22,Forecast!P44) -> 39159.274 | ... T10: =CHOOSE('Income Statement'!$C$2,Forecast!T33,Forecast!T22,Forecast!T44) -> 43003.214
B11: =B23 -> 11268 | C11: =C23 -> HR | D11: =D23 -> Meetups | E11: =E23 -> 60285 | F11: =F23 -> 61225 | G11: =G23 -> 68994 | H11: =H23 -> 72410 | I11: =CHOOSE('Income Statement'!$C$2,Forecast!I34,Forecast!I23,Forecast!I45) -> 53693.925 | J11: =CHOOSE('Income Statement'!$C$2,Forecast!J34,Forecast!J23,Forecast!J45) -> 56511.928 | K11: =CHOOSE('Income Statement'!$C$2,Forecast!K34,Forecast!K23,Forecast!K45) -> 60962.76 | L11: =CHOOSE('Income Statement'!$C$2,Forecast!L34,Forecast!L23,Forecast!L45) -> 63613.011 | M11: =CHOOSE('Income Statement'!$C$2,Forecast!M34,Forecast!M23,Forecast!M45) -> 67863.644 | N11: =CHOOSE('Income Statement'!$C$2,Forecast!N34,Forecast!N23,Forecast!N45) -> 70560.152 | O11: =CHOOSE('Income Statement'!$C$2,Forecast!O34,Forecast!O23,Forecast!O45) -> 74806.187 | P11: =CHOOSE('Income Statement'!$C$2,Forecast!P34,Forecast!P23,Forecast!P45) -> 77725.223 | ... T11: =CHOOSE('Income Statement'!$C$2,Forecast!T34,Forecast!T23,Forecast!T45) -> 91760.115
B14: 1. Base Case | E14: Actuals | I14: Forecast
A15: x | B15: ='Actual Expenses'!B5 -> Account # | C15: ='Actual Expenses'!C5 -> Department | D15: ='Actual Expenses'!D5 -> Description | E15: ='Actual Expenses'!E5 -> 45536 | F15: ='Actual Expenses'!F5 -> 45566 | G15: ='Actual Expenses'!G5 -> 45597 | H15: ='Actual Expenses'!H5 -> 45627 | I15: =EDATE(H15,1) -> 45658 | J15: =EDATE(I15,1) -> 45689 | K15: =EDATE(J15,1) -> 45717 | L15: =EDATE(K15,1) -> 45748 | M15: =EDATE(L15,1) -> 45778 | N15: =EDATE(M15,1) -> 45809 | O15: =EDATE(N15,1) -> 45839 | P15: =EDATE(O15,1) -> 45870 | ... T15: =EDATE(S15,1) -> 45992
B16: ='Actual Expenses'!B6 -> 11256 | C16: ='Actual Expenses'!C6 -> Marketing | D16: ='Actual Expenses'!D6 -> Paid Ads | E16: ='Actual Expenses'!E6 -> 22992 | F16: ='Actual Expenses'!F6 -> 24001 | G16: ='Actual Expenses'!G6 -> 26558 | H16: ='Actual Expenses'!H6 -> 25446 | I16: =_xlfn.FORECAST.ETS(I$15,$E16:H16,$E$15:H$15) -> 26859.761 | J16: =_xlfn.FORECAST.ETS(J$15,$E16:I16,$E$15:I$15) -> 26922.594 | K16: =_xlfn.FORECAST.ETS(K$15,$E16:J16,$E$15:J$15) -> 28560.22 | L16: =_xlfn.FORECAST.ETS(L$15,$E16:K16,$E$15:K$15) -> 28501.432 | M16: =_xlfn.FORECAST.ETS(M$15,$E16:L16,$E$15:L$15) -> 30101.347 | N16: =_xlfn.FORECAST.ETS(N$15,$E16:M16,$E$15:M$15) -> 30111.719 | O16: =_xlfn.FORECAST.ETS(O$15,$E16:N16,$E$15:N$15) -> 31672.189 | P16: =_xlfn.FORECAST.ETS(P$15,$E16:O16,$E$15:O$15) -> 31683.439 | ... T16: =_xlfn.FORECAST.ETS(T$15,$E16:S16,$E$15:S$15) -> 34816.87
B17: ='Actual Expenses'!B7 -> 11257 | C17: ='Actual Expenses'!C7 -> Marketing | D17: ='Actual Expenses'!D7 -> Infuencers | E17: ='Actual Expenses'!E7 -> 53326 | F17: ='Actual Expenses'!F7 -> 54223 | G17: ='Actual Expenses'!G7 -> 51000 | H17: ='Actual Expenses'!H7 -> 50000 | I17: =_xlfn.FORECAST.ETS(I$15,$E17:H17,$E$15:H$15) -> 48858.544 | J17: =_xlfn.FORECAST.ETS(J$15,$E17:I17,$E$15:I$15) -> 47585.966 | K17: =_xlfn.FORECAST.ETS(K$15,$E17:J17,$E$15:J$15) -> 45844.021 | L17: =_xlfn.FORECAST.ETS(L$15,$E17:K17,$E$15:K$15) -> 44591.391 | M17: =_xlfn.FORECAST.ETS(M$15,$E17:L17,$E$15:L$15) -> 42871.655 | N17: =_xlfn.FORECAST.ETS(N$15,$E17:M17,$E$15:M$15) -> 41659.495 | O17: =_xlfn.FORECAST.ETS(O$15,$E17:N17,$E$15:N$15) -> 39701.198 | P17: =_xlfn.FORECAST.ETS(P$15,$E17:O17,$E$15:O$15) -> 38527.277 | ... T17: =_xlfn.FORECAST.ETS(T$15,$E17:S17,$E$15:S$15) -> 32319.266
B18: ='Actual Expenses'!B8 -> 11259 | C18: ='Actual Expenses'!C8 -> Engineering | D18: ='Actual Expenses'!D8 -> Consulting | E18: ='Actual Expenses'!E8 -> 35888 | F18: ='Actual Expenses'!F8 -> 36880 | G18: ='Actual Expenses'!G8 -> 37995 | H18: ='Actual Expenses'!H8 -> 40000 | I18: =_xlfn.FORECAST.ETS(I$15,$E18:H18,$E$15:H$15) -> 41183.971 | J18: =_xlfn.FORECAST.ETS(J$15,$E18:I18,$E$15:I$15) -> 42613.672 | K18: =_xlfn.FORECAST.ETS(K$15,$E18:J18,$E$15:J$15) -> 44036.168 | L18: =_xlfn.FORECAST.ETS(L$15,$E18:K18,$E$15:K$15) -> 45413.912 | M18: =_xlfn.FORECAST.ETS(M$15,$E18:L18,$E$15:L$15) -> 46814.567 | N18: =_xlfn.FORECAST.ETS(N$15,$E18:M18,$E$15:M$15) -> 48215.311 | O18: =_xlfn.FORECAST.ETS(O$15,$E18:N18,$E$15:N$15) -> 49616.148 | P18: =_xlfn.FORECAST.ETS(P$15,$E18:O18,$E$15:O$15) -> 51017.052 | ... T18: =_xlfn.FORECAST.ETS(T$15,$E18:S18,$E$15:S$15) -> 56620.877
B19: ='Actual Expenses'!B9 -> 11260 | C19: ='Actual Expenses'!C9 -> Engineering | D19: ='Actual Expenses'!D9 -> Travel | E19: ='Actual Expenses'!E9 -> 87942 | F19: ='Actual Expenses'!F9 -> 85224 | G19: ='Actual Expenses'!G9 -> 82469 | H19: ='Actual Expenses'!H9 -> 81005 | I19: =_xlfn.FORECAST.ETS(I$15,$E19:H19,$E$15:H$15) -> 78427.892 | J19: =_xlfn.FORECAST.ETS(J$15,$E19:I19,$E$15:I$15) -> 76178.043 | K19: =_xlfn.FORECAST.ETS(K$15,$E19:J19,$E$15:J$15) -> 73912.465 | L19: =_xlfn.FORECAST.ETS(L$15,$E19:K19,$E$15:K$15) -> 71611.91 | M19: =_xlfn.FORECAST.ETS(M$15,$E19:L19,$E$15:L$15) -> 69331.893 | N19: =_xlfn.FORECAST.ETS(N$15,$E19:M19,$E$15:M$15) -> 67050.575 | O19: =_xlfn.FORECAST.ETS(O$15,$E19:N19,$E$15:N$15) -> 64768.401 | P19: =_xlfn.FORECAST.ETS(P$15,$E19:O19,$E$15:O$15) -> 62480.729 | ... T19: =_xlfn.FORECAST.ETS(T$15,$E19:S19,$E$15:S$15) -> 53344.816
B20: ='Actual Expenses'!B10 -> 11263 | C20: ='Actual Expenses'!C10 -> Support | D20: ='Actual Expenses'!D10 -> Software | E20: ='Actual Expenses'!E10 -> 92622 | F20: ='Actual Expenses'!F10 -> 90005 | G20: ='Actual Expenses'!G10 -> 87556 | H20: ='Actual Expenses'!H10 -> 84522 | I20: =_xlfn.FORECAST.ETS(I$15,$E20:H20,$E$15:H$15) -> 81916.877 | J20: =_xlfn.FORECAST.ETS(J$15,$E20:I20,$E$15:I$15) -> 79206.408 | K20: =_xlfn.FORECAST.ETS(K$15,$E20:J20,$E$15:J$15) -> 76483.45 | L20: =_xlfn.FORECAST.ETS(L$15,$E20:K20,$E$15:K$15) -> 73792.488 | M20: =_xlfn.FORECAST.ETS(M$15,$E20:L20,$E$15:L$15) -> 71086.198 | N20: =_xlfn.FORECAST.ETS(N$15,$E20:M20,$E$15:M$15) -> 68267.761 | O20: =_xlfn.FORECAST.ETS(O$15,$E20:N20,$E$15:N$15) -> 65623.68 | P20: =_xlfn.FORECAST.ETS(P$15,$E20:O20,$E$15:O$15) -> 62955.109 | ... T20: =_xlfn.FORECAST.ETS(T$15,$E20:S20,$E$15:S$15) -> 51987.35
B21: ='Actual Expenses'!B11 -> 11264 | C21: ='Actual Expenses'!C11 -> Support | D21: ='Actual Expenses'!D11 -> Call Center | E21: ='Actual Expenses'!E11 -> 27416 | F21: ='Actual Expenses'!F11 -> 26554 | G21: ='Actual Expenses'!G11 -> 24330 | H21: ='Actual Expenses'!H11 -> 22338 | I21: =_xlfn.FORECAST.ETS(I$15,$E21:H21,$E$15:H$15) -> 20784.677 | J21: =_xlfn.FORECAST.ETS(J$15,$E21:I21,$E$15:I$15) -> 18966.367 | K21: =_xlfn.FORECAST.ETS(K$15,$E21:J21,$E$15:J$15) -> 17138.765 | L21: =_xlfn.FORECAST.ETS(L$15,$E21:K21,$E$15:K$15) -> 15398.473 | M21: =_xlfn.FORECAST.ETS(M$15,$E21:L21,$E$15:L$15) -> 13625.108 | N21: =_xlfn.FORECAST.ETS(N$15,$E21:M21,$E$15:M$15) -> 11459.691 | O21: =_xlfn.FORECAST.ETS(O$15,$E21:N21,$E$15:N$15) -> 10235.714 | P21: =_xlfn.FORECAST.ETS(P$15,$E21:O21,$E$15:O$15) -> 8271.2763 | ... T21: =_xlfn.FORECAST.ETS(T$15,$E21:S21,$E$15:S$15) -> 825.90662
B22: ='Actual Expenses'!B12 -> 11267 | C22: ='Actual Expenses'!C12 -> HR | D22: ='Actual Expenses'!D12 -> Recruiting Events | E22: ='Actual Expenses'!E12 -> 41696 | F22: ='Actual Expenses'!F12 -> 41696 | G22: ='Actual Expenses'!G12 -> 42558 | H22: ='Actual Expenses'!H12 -> 45448 | I22: =_xlfn.FORECAST.ETS(I$15,$E22:H22,$E$15:H$15) -> 46256.947 | J22: =_xlfn.FORECAST.ETS(J$15,$E22:I22,$E$15:I$15) -> 47704.638 | K22: =_xlfn.FORECAST.ETS(K$15,$E22:J22,$E$15:J$15) -> 49150.171 | L22: =_xlfn.FORECAST.ETS(L$15,$E22:K22,$E$15:K$15) -> 50452.329 | M22: =_xlfn.FORECAST.ETS(M$15,$E22:L22,$E$15:L$15) -> 51824.343 | N22: =_xlfn.FORECAST.ETS(N$15,$E22:M22,$E$15:M$15) -> 53196.599 | O22: =_xlfn.FORECAST.ETS(O$15,$E22:N22,$E$15:N$15) -> 54569.117 | P22: =_xlfn.FORECAST.ETS(P$15,$E22:O22,$E$15:O$15) -> 55941.82 | ... T22: =_xlfn.FORECAST.ETS(T$15,$E22:S22,$E$15:S$15) -> 61433.162
B23: ='Actual Expenses'!B13 -> 11268 | C23: ='Actual Expenses'!C13 -> HR | D23: ='Actual Expenses'!D13 -> Meetups | E23: ='Actual Expenses'!E13 -> 60285 | F23: ='Actual Expenses'!F13 -> 61225 | G23: ='Actual Expenses'!G13 -> 68994 | H23: ='Actual Expenses'!H13 -> 72410 | I23: =_xlfn.FORECAST.ETS(I$15,$E23:H23,$E$15:H$15) -> 76705.607 | J23: =_xlfn.FORECAST.ETS(J$15,$E23:I23,$E$15:I$15) -> 80731.326 | K23: =_xlfn.FORECAST.ETS(K$15,$E23:J23,$E$15:J$15) -> 87089.658 | L23: =_xlfn.FORECAST.ETS(L$15,$E23:K23,$E$15:K$15) -> 90875.73 | M23: =_xlfn.FORECAST.ETS(M$15,$E23:L23,$E$15:L$15) -> 96948.062 | N23: =_xlfn.FORECAST.ETS(N$15,$E23:M23,$E$15:M$15) -> 100800.22 | O23: =_xlfn.FORECAST.ETS(O$15,$E23:N23,$E$15:N$15) -> 106865.98 | P23: =_xlfn.FORECAST.ETS(P$15,$E23:O23,$E$15:O$15) -> 111036.03 | ... T23: =_xlfn.FORECAST.ETS(T$15,$E23:S23,$E$15:S$15) -> 131085.88
B25: 2. Best Case | E25: Actuals | I25: Forecast
A26: x | B26: =B15 -> Account # | C26: =C15 -> Department | D26: =D15 -> Description | E26: =E15 -> 45536 | F26: =F15 -> 45566 | G26: =G15 -> 45597 | H26: =H15 -> 45627 | I26: =EDATE(H26,1) -> 45658 | J26: =EDATE(I26,1) -> 45689 | K26: =EDATE(J26,1) -> 45717 | L26: =EDATE(K26,1) -> 45748 | M26: =EDATE(L26,1) -> 45778 | N26: =EDATE(M26,1) -> 45809 | O26: =EDATE(N26,1) -> 45839 | P26: =EDATE(O26,1) -> 45870 | ... T26: =EDATE(S26,1) -> 45992
B27: =B16 -> 11256 | C27: =C16 -> Marketing | D27: =D16 -> Paid Ads | E27: =E16 -> 22992 | F27: =F16 -> 24001 | G27: =G16 -> 26558 | H27: =H16 -> 25446 | I27: =I16*(1+$C$48) -> 34917.689 | J27: =J16*(1+$C$48) -> 34999.372 | K27: =K16*(1+$C$48) -> 37128.286 | L27: =L16*(1+$C$48) -> 37051.862 | M27: =M16*(1+$C$48) -> 39131.751 | N27: =N16*(1+$C$48) -> 39145.235 | O27: =O16*(1+$C$48) -> 41173.846 | P27: =P16*(1+$C$48) -> 41188.471 | ... T27: =T16*(1+$C$48) -> 45261.932
B28: =B17 -> 11257 | C28: =C17 -> Marketing | D28: =D17 -> Infuencers | E28: =E17 -> 53326 | F28: =F17 -> 54223 | G28: =G17 -> 51000 | H28: =H17 -> 50000 | I28: =I17*(1-$C$48) -> 34200.981 | J28: =J17*(1-$C$48) -> 33310.176 | K28: =K17*(1-$C$48) -> 32090.815 | L28: =L17*(1-$C$48) -> 31213.974 | M28: =M17*(1-$C$48) -> 30010.158 | N28: =N17*(1-$C$48) -> 29161.646 | O28: =O17*(1-$C$48) -> 27790.839 | P28: =P17*(1-$C$48) -> 26969.094 | ... T28: =T17*(1-$C$48) -> 22623.486
B29: =B18 -> 11259 | C29: =C18 -> Engineering | D29: =D18 -> Consulting | E29: =E18 -> 35888 | F29: =F18 -> 36880 | G29: =G18 -> 37995 | H29: =H18 -> 40000 | I29: =I18*(1-$C$48) -> 28828.78 | J29: =J18*(1-$C$48) -> 29829.57 | K29: =K18*(1-$C$48) -> 30825.318 | L29: =L18*(1-$C$48) -> 31789.738 | M29: =M18*(1-$C$48) -> 32770.197 | N29: =N18*(1-$C$48) -> 33750.718 | O29: =O18*(1-$C$48) -> 34731.303 | P29: =P18*(1-$C$48) -> 35711.936 | ... T29: =T18*(1-$C$48) -> 39634.614
B30: =B19 -> 11260 | C30: =C19 -> Engineering | D30: =D19 -> Travel | E30: =E19 -> 87942 | F30: =F19 -> 85224 | G30: =G19 -> 82469 | H30: =H19 -> 81005 | I30: =I19*(1-$C$48) -> 54899.524 | J30: =J19*(1-$C$48) -> 53324.63 | K30: =K19*(1-$C$48) -> 51738.726 | L30: =L19*(1-$C$48) -> 50128.337 | M30: =M19*(1-$C$48) -> 48532.325 | N30: =N19*(1-$C$48) -> 46935.402 | O30: =O19*(1-$C$48) -> 45337.88 | P30: =P19*(1-$C$48) -> 43736.51 | ... T30: =T19*(1-$C$48) -> 37341.371
B31: =B20 -> 11263 | C31: =C20 -> Support | D31: =D20 -> Software | E31: =E20 -> 92622 | F31: =F20 -> 90005 | G31: =G20 -> 87556 | H31: =H20 -> 84522 | I31: =I20*(1-$C$48) -> 57341.814 | J31: =J20*(1-$C$48) -> 55444.485 | K31: =K20*(1-$C$48) -> 53538.415 | L31: =L20*(1-$C$48) -> 51654.742 | M31: =M20*(1-$C$48) -> 49760.338 | N31: =N20*(1-$C$48) -> 47787.432 | O31: =O20*(1-$C$48) -> 45936.576 | P31: =P20*(1-$C$48) -> 44068.577 | ... T31: =T20*(1-$C$48) -> 36391.145
B32: =B21 -> 11264 | C32: =C21 -> Support | D32: =D21 -> Call Center | E32: =E21 -> 27416 | F32: =F21 -> 26554 | G32: =G21 -> 24330 | H32: =H21 -> 22338 | I32: =I21*(1-$C$48) -> 14549.274 | J32: =J21*(1-$C$48) -> 13276.457 | K32: =K21*(1-$C$48) -> 11997.136 | L32: =L21*(1-$C$48) -> 10778.931 | M32: =M21*(1-$C$48) -> 9537.5757 | N32: =N21*(1-$C$48) -> 8021.7835 | O32: =O21*(1-$C$48) -> 7164.9997 | P32: =P21*(1-$C$48) -> 5789.8934 | ... T32: =T21*(1-$C$48) -> 578.13463
B33: =B22 -> 11267 | C33: =C22 -> HR | D33: =D22 -> Recruiting Events | E33: =E22 -> 41696 | F33: =F22 -> 41696 | G33: =G22 -> 42558 | H33: =H22 -> 45448 | I33: =I22*(1-$C$48) -> 32379.863 | J33: =J22*(1-$C$48) -> 33393.247 | K33: =K22*(1-$C$48) -> 34405.12 | L33: =L22*(1-$C$48) -> 35316.63 | M33: =M22*(1-$C$48) -> 36277.04 | N33: =N22*(1-$C$48) -> 37237.62 | O33: =O22*(1-$C$48) -> 38198.382 | P33: =P22*(1-$C$48) -> 39159.274 | ... T33: =T22*(1-$C$48) -> 43003.214
B34: =B23 -> 11268 | C34: =C23 -> HR | D34: =D23 -> Meetups | E34: =E23 -> 60285 | F34: =F23 -> 61225 | G34: =G23 -> 68994 | H34: =H23 -> 72410 | I34: =I23*(1-$C$48) -> 53693.925 | J34: =J23*(1-$C$48) -> 56511.928 | K34: =K23*(1-$C$48) -> 60962.76 | L34: =L23*(1-$C$48) -> 63613.011 | M34: =M23*(1-$C$48) -> 67863.644 | N34: =N23*(1-$C$48) -> 70560.152 | O34: =O23*(1-$C$48) -> 74806.187 | P34: =P23*(1-$C$48) -> 77725.223 | ... T34: =T23*(1-$C$48) -> 91760.115
B36: 3. Worst Case | E36: Actuals | I36: Forecast
B37: =B26 -> Account # | C37: =C26 -> Department | D37: =D26 -> Description | E37: =E26 -> 45536 | F37: =F26 -> 45566 | G37: =G26 -> 45597 | H37: =H26 -> 45627 | I37: =EDATE(H37,1) -> 45658 | J37: =EDATE(I37,1) -> 45689 | K37: =EDATE(J37,1) -> 45717 | L37: =EDATE(K37,1) -> 45748 | M37: =EDATE(L37,1) -> 45778 | N37: =EDATE(M37,1) -> 45809 | O37: =EDATE(N37,1) -> 45839 | P37: =EDATE(O37,1) -> 45870 | ... T37: =EDATE(S37,1) -> 45992
B38: =B27 -> 11256 | C38: =C27 -> Marketing | D38: =D27 -> Paid Ads | E38: =E27 -> 22992 | F38: =F27 -> 24001 | G38: =G27 -> 26558 | H38: =H27 -> 25446 | I38: =I16*(1-$C$49) -> 18801.833 | J38: =J16*(1-$C$49) -> 18845.815 | K38: =K16*(1-$C$49) -> 19992.154 | L38: =L16*(1-$C$49) -> 19951.002 | M38: =M16*(1-$C$49) -> 21070.943 | N38: =N16*(1-$C$49) -> 21078.203 | O38: =O16*(1-$C$49) -> 22170.533 | P38: =P16*(1-$C$49) -> 22178.407 | ... T38: =T16*(1-$C$49) -> 24371.809
B39: =B28 -> 11257 | C39: =C28 -> Marketing | D39: =D28 -> Infuencers | E39: =E28 -> 53326 | F39: =F28 -> 54223 | G39: =G28 -> 51000 | H39: =H28 -> 50000 | I39: =I17*(1+$C$49) -> 63516.107 | J39: =J17*(1+$C$49) -> 61861.756 | K39: =K17*(1+$C$49) -> 59597.227 | L39: =L17*(1+$C$49) -> 57968.808 | M39: =M17*(1+$C$49) -> 55733.151 | N39: =N17*(1+$C$49) -> 54157.343 | O39: =O17*(1+$C$49) -> 51611.558 | P39: =P17*(1+$C$49) -> 50085.461 | ... T39: =T17*(1+$C$49) -> 42015.045
B40: =B29 -> 11259 | C40: =C29 -> Engineering | D40: =D29 -> Consulting | E40: =E29 -> 35888 | F40: =F29 -> 36880 | G40: =G29 -> 37995 | H40: =H29 -> 40000 | I40: =I18*(1+$C$49) -> 53539.163 | J40: =J18*(1+$C$49) -> 55397.773 | K40: =K18*(1+$C$49) -> 57247.018 | L40: =L18*(1+$C$49) -> 59038.085 | M40: =M18*(1+$C$49) -> 60858.938 | N40: =N18*(1+$C$49) -> 62679.904 | O40: =O18*(1+$C$49) -> 64500.992 | P40: =P18*(1+$C$49) -> 66322.167 | ... T40: =T18*(1+$C$49) -> 73607.14
B41: =B30 -> 11260 | C41: =C30 -> Engineering | D41: =D30 -> Travel | E41: =E30 -> 87942 | F41: =F30 -> 85224 | G41: =G30 -> 82469 | H41: =H30 -> 81005 | I41: =I19*(1+$C$49) -> 101956.26 | J41: =J19*(1+$C$49) -> 99031.456 | K41: =K19*(1+$C$49) -> 96086.205 | L41: =L19*(1+$C$49) -> 93095.483 | M41: =M19*(1+$C$49) -> 90131.461 | N41: =N19*(1+$C$49) -> 87165.747 | O41: =O19*(1+$C$49) -> 84198.921 | P41: =P19*(1+$C$49) -> 81224.948 | ... T41: =T19*(1+$C$49) -> 69348.261
B42: =B31 -> 11263 | C42: =C31 -> Support | D42: =D31 -> Software | E42: =E31 -> 92622 | F42: =F31 -> 90005 | G42: =G31 -> 87556 | H42: =H31 -> 84522 | I42: =I20*(1+$C$49) -> 106491.94 | J42: =J20*(1+$C$49) -> 102968.33 | K42: =K20*(1+$C$49) -> 99428.485 | L42: =L20*(1+$C$49) -> 95930.234 | M42: =M20*(1+$C$49) -> 92412.057 | N42: =N20*(1+$C$49) -> 88748.089 | O42: =O20*(1+$C$49) -> 85310.784 | P42: =P20*(1+$C$49) -> 81841.642 | ... T42: =T20*(1+$C$49) -> 67583.555
B43: =B32 -> 11264 | C43: =C32 -> Support | D43: =D32 -> Call Center | E43: =E32 -> 27416 | F43: =F32 -> 26554 | G43: =G32 -> 24330 | H43: =H32 -> 22338 | I43: =I21*(1+$C$49) -> 27020.08 | J43: =J21*(1+$C$49) -> 24656.278 | K43: =K21*(1+$C$49) -> 22280.395 | L43: =L21*(1+$C$49) -> 20018.015 | M43: =M21*(1+$C$49) -> 17712.641 | N43: =N21*(1+$C$49) -> 14897.598 | O43: =O21*(1+$C$49) -> 13306.428 | P43: =P21*(1+$C$49) -> 10752.659 | ... T43: =T21*(1+$C$49) -> 1073.6786
B44: =B33 -> 11267 | C44: =C33 -> HR | D44: =D33 -> Recruiting Events | E44: =E33 -> 41696 | F44: =F33 -> 41696 | G44: =G33 -> 42558 | H44: =H33 -> 45448 | I44: =I22*(1+$C$49) -> 60134.031 | J44: =J22*(1+$C$49) -> 62016.029 | K44: =K22*(1+$C$49) -> 63895.223 | L44: =L22*(1+$C$49) -> 65588.027 | M44: =M22*(1+$C$49) -> 67371.646 | N44: =N22*(1+$C$49) -> 69155.579 | O44: =O22*(1+$C$49) -> 70939.852 | P44: =P22*(1+$C$49) -> 72724.366 | ... T44: =T22*(1+$C$49) -> 79863.111
A45: x | B45: =B34 -> 11268 | C45: =C34 -> HR | D45: =D34 -> Meetups | E45: =E34 -> 60285 | F45: =F34 -> 61225 | G45: =G34 -> 68994 | H45: =H34 -> 72410 | I45: =I23*(1+$C$49) -> 99717.289 | J45: =J23*(1+$C$49) -> 104950.72 | K45: =K23*(1+$C$49) -> 113216.56 | L45: =L23*(1+$C$49) -> 118138.45 | M45: =M23*(1+$C$49) -> 126032.48 | N45: =N23*(1+$C$49) -> 131040.28 | O45: =O23*(1+$C$49) -> 138925.78 | P45: =P23*(1+$C$49) -> 144346.84 | ... T45: =T23*(1+$C$49) -> 170411.64
...

Sheet Income Statement
B2: Operating Expenses Scenario | C2: 1
A4: x | B4: Income Statement Forecast
B5: in USD | C5: =Forecast!I15 -> 45658 | D5: =Forecast!J15 -> 45689 | E5: =Forecast!K15 -> 45717 | F5: =Forecast!L15 -> 45748 | G5: =Forecast!M15 -> 45778 | H5: =Forecast!N15 -> 45809 | I5: =Forecast!O15 -> 45839 | J5: =Forecast!P15 -> 45870 | ... N5: =Forecast!T15 -> 45992
B6: Revenue | C6: =C31 -> 642803.63 | D6: =D31 -> 635278.8 | E6: =E31 -> 643737.63 | F6: =F31 -> 634872.27 | G6: =G31 -> 643019.76 | H6: =H31 -> 816950.3 | I6: =I31 -> 824817.63 | J6: =J31 -> 815164.47 | ... N6: =N31 -> 811909.59
B7: COGS | C7: =C35 -> 192841.09 | D7: =D35 -> 190583.64 | E7: =E35 -> 193121.29 | F7: =F35 -> 190461.68 | G7: =G35 -> 192905.93 | H7: =H35 -> 245085.09 | I7: =I35 -> 247445.29 | J7: =J35 -> 244549.34 | ... N7: =N35 -> 243572.88
B8: Gross Profit | C8: =C6-C7 -> 449962.54 | D8: =D6-D7 -> 444695.16 | E8: =E6-E7 -> 450616.34 | F8: =F6-F7 -> 444410.59 | G8: =G6-G7 -> 450113.83 | H8: =H6-H7 -> 571865.21 | I8: =I6-I7 -> 577372.34 | J8: =J6-J7 -> 570615.13 | ... N8: =N6-N7 -> 568336.72
B10: Operating expenses:
B11: {=_xlfn.UNIQUE(Forecast!C16:C23)} -> Marketing | C11: =SUMIFS(Forecast!I$4:I$11,Forecast!$C$4:$C$11,'Income Statement'!$B11) -> 69118.67 | D11: =SUMIFS(Forecast!J$4:J$11,Forecast!$C$4:$C$11,'Income Statement'!$B11) -> 68309.548 | E11: =SUMIFS(Forecast!K$4:K$11,Forecast!$C$4:$C$11,'Income Statement'!$B11) -> 69219.1 | F11: =SUMIFS(Forecast!L$4:L$11,Forecast!$C$4:$C$11,'Income Statement'!$B11) -> 68265.835 | G11: =SUMIFS(Forecast!M$4:M$11,Forecast!$C$4:$C$11,'Income Statement'!$B11) -> 69141.909 | H11: =SUMIFS(Forecast!N$4:N$11,Forecast!$C$4:$C$11,'Income Statement'!$B11) -> 68306.881 | I11: =SUMIFS(Forecast!O$4:O$11,Forecast!$C$4:$C$11,'Income Statement'!$B11) -> 68964.685 | J11: =SUMIFS(Forecast!P$4:P$11,Forecast!$C$4:$C$11,'Income Statement'!$B11) -> 68157.565 | ... N11: =SUMIFS(Forecast!T$4:T$11,Forecast!$C$4:$C$11,'Income Statement'!$B11) -> 67885.418
B12: Engineering | C12: =SUMIFS(Forecast!I$4:I$11,Forecast!$C$4:$C$11,'Income Statement'!$B12) -> 83728.304 | D12: =SUMIFS(Forecast!J$4:J$11,Forecast!$C$4:$C$11,'Income Statement'!$B12) -> 83154.201 | E12: =SUMIFS(Forecast!K$4:K$11,Forecast!$C$4:$C$11,'Income Statement'!$B12) -> 82564.043 | F12: =SUMIFS(Forecast!L$4:L$11,Forecast!$C$4:$C$11,'Income Statement'!$B12) -> 81918.076 | G12: =SUMIFS(Forecast!M$4:M$11,Forecast!$C$4:$C$11,'Income Statement'!$B12) -> 81302.522 | H12: =SUMIFS(Forecast!N$4:N$11,Forecast!$C$4:$C$11,'Income Statement'!$B12) -> 80686.12 | I12: =SUMIFS(Forecast!O$4:O$11,Forecast!$C$4:$C$11,'Income Statement'!$B12) -> 80069.184 | J12: =SUMIFS(Forecast!P$4:P$11,Forecast!$C$4:$C$11,'Income Statement'!$B12) -> 79448.446 | ... N12: =SUMIFS(Forecast!T$4:T$11,Forecast!$C$4:$C$11,'Income Statement'!$B12) -> 76975.985
B13: Support | C13: =SUMIFS(Forecast!I$4:I$11,Forecast!$C$4:$C$11,'Income Statement'!$B13) -> 71891.087 | D13: =SUMIFS(Forecast!J$4:J$11,Forecast!$C$4:$C$11,'Income Statement'!$B13) -> 68720.943 | E13: =SUMIFS(Forecast!K$4:K$11,Forecast!$C$4:$C$11,'Income Statement'!$B13) -> 65535.551 | F13: =SUMIFS(Forecast!L$4:L$11,Forecast!$C$4:$C$11,'Income Statement'!$B13) -> 62433.673 | G13: =SUMIFS(Forecast!M$4:M$11,Forecast!$C$4:$C$11,'Income Statement'!$B13) -> 59297.914 | H13: =SUMIFS(Forecast!N$4:N$11,Forecast!$C$4:$C$11,'Income Statement'!$B13) -> 55809.216 | I13: =SUMIFS(Forecast!O$4:O$11,Forecast!$C$4:$C$11,'Income Statement'!$B13) -> 53101.576 | J13: =SUMIFS(Forecast!P$4:P$11,Forecast!$C$4:$C$11,'Income Statement'!$B13) -> 49858.47 | ... N13: =SUMIFS(Forecast!T$4:T$11,Forecast!$C$4:$C$11,'Income Statement'!$B13) -> 36969.279
B14: HR | C14: =SUMIFS(Forecast!I$4:I$11,Forecast!$C$4:$C$11,'Income Statement'!$B14) -> 86073.787 | D14: =SUMIFS(Forecast!J$4:J$11,Forecast!$C$4:$C$11,'Income Statement'!$B14) -> 89905.175 | E14: =SUMIFS(Forecast!K$4:K$11,Forecast!$C$4:$C$11,'Income Statement'!$B14) -> 95367.88 | F14: =SUMIFS(Forecast!L$4:L$11,Forecast!$C$4:$C$11,'Income Statement'!$B14) -> 98929.641 | G14: =SUMIFS(Forecast!M$4:M$11,Forecast!$C$4:$C$11,'Income Statement'!$B14) -> 104140.68 | H14: =SUMIFS(Forecast!N$4:N$11,Forecast!$C$4:$C$11,'Income Statement'!$B14) -> 107797.77 | I14: =SUMIFS(Forecast!O$4:O$11,Forecast!$C$4:$C$11,'Income Statement'!$B14) -> 113004.57 | J14: =SUMIFS(Forecast!P$4:P$11,Forecast!$C$4:$C$11,'Income Statement'!$B14) -> 116884.5 | ... N14: =SUMIFS(Forecast!T$4:T$11,Forecast!$C$4:$C$11,'Income Statement'!$B14) -> 134763.33
B15: Total operating expenses | C15: =SUM(C11:C14) -> 310811.85 | D15: =SUM(D11:D14) -> 310089.87 | E15: =SUM(E11:E14) -> 312686.57 | F15: =SUM(F11:F14) -> 311547.22 | G15: =SUM(G11:G14) -> 313883.03 | H15: =SUM(H11:H14) -> 312599.99 | I15: =SUM(I11:I14) -> 315140.01 | J15: =SUM(J11:J14) -> 314348.98 | ... N15: =SUM(N11:N14) -> 316594.01
B16: Operating income | C16: =C8-C15 -> 139150.69 | D16: =D8-D15 -> 134605.29 | E16: =E8-E15 -> 137929.77 | F16: =F8-F15 -> 132863.36 | G16: =G8-G15 -> 136230.8 | H16: =H8-H15 -> 259265.22 | I16: =I8-I15 -> 262232.33 | J16: =J8-J15 -> 256266.15 | ... N16: =N8-N15 -> 251742.7
B18: Other income / (expense), net | C18: =C38 -> 4821.0272 | D18: =D38 -> 4764.591 | E18: =E38 -> 4828.0323 | F18: =F38 -> 4761.542 | G18: =G38 -> 4822.6482 | H18: =H38 -> 6127.1272 | I18: =I38 -> 6186.1323 | J18: =J38 -> 6113.7336 | ... N18: =N38 -> 6089.322
B19: Pre-tax income | C19: =C16-C18 -> 134329.67 | D19: =D16-D18 -> 129840.7 | E19: =E16-E18 -> 133101.74 | F19: =F16-F18 -> 128101.82 | G19: =G16-G18 -> 131408.15 | H19: =H16-H18 -> 253138.09 | I19: =I16-I18 -> 256046.2 | J19: =J16-J18 -> 250152.42 | ... N19: =N16-N18 -> 245653.38
B21: Taxes | C21: =C19*$C$40 -> 33582.416 | D21: =D19*$C$40 -> 32460.175 | E21: =E19*$C$40 -> 33275.434 | F21: =F19*$C$40 -> 32025.455 | G21: =G19*$C$40 -> 32852.038 | H21: =H19*$C$40 -> 63284.523 | I21: =I19*$C$40 -> 64011.55 | J21: =J19*$C$40 -> 62538.105 | ... N21: =N19*$C$40 -> 61413.346
B22: Net Income | C22: =C19-C21 -> 100747.25 | D22: =D19-D21 -> 97380.526 | E22: =E19-E21 -> 99826.303 | F22: =F19-F21 -> 96076.365 | G22: =G19-G21 -> 98556.114 | H22: =H19-H21 -> 189853.57 | I22: =I19-I21 -> 192034.65 | J22: =J19-J21 -> 187614.31 | ... N22: =N19-N21 -> 184240.04
A25: x | B25: Assumptions
B26: Revenue
B27: Customer Acquisition Cost | C27: 30 | D27: 30 | E27: 30 | F27: 30 | G27: 30 | H27: 25 | I27: 25 | J27: 25 | K27: 25 | L27: 25 | M27: 25 | N27: 25
B28: Price | C28: 279 | D28: 279 | E28: 279 | F28: 279 | G28: 279 | H28: 299 | I28: 299 | J28: 299 | K28: 299 | L28: 299 | M28: 299 | N28: 299
B30: Units Sold | C30: =C11/C27 -> 2303.9557 | D30: =D11/D27 -> 2276.9849 | E30: =E11/E27 -> 2307.3033 | F30: =F11/F27 -> 2275.5278 | G30: =G11/G27 -> 2304.7303 | H30: =H11/H27 -> 2732.2752 | I30: =I11/I27 -> 2758.5874 | J30: =J11/J27 -> 2726.3026 | ... N30: =N11/N27 -> 2715.4167
B31: Revenue | C31: =C30*C28 -> 642803.63 | D31: =D30*D28 -> 635278.8 | E31: =E30*E28 -> 643737.63 | F31: =F30*F28 -> 634872.27 | G31: =G30*G28 -> 643019.76 | H31: =H30*H28 -> 816950.3 | I31: =I30*I28 -> 824817.63 | J31: =J30*J28 -> 815164.47 | ... N31: =N30*N28 -> 811909.59
B33: Other
B34: COGS % of Revenue | C34: 0.3 | D34: 0.3 | E34: 0.3 | F34: 0.3 | G34: 0.3 | H34: 0.3 | I34: 0.3 | J34: 0.3 | K34: 0.3 | L34: 0.3 | M34: 0.3 | N34: 0.3
B35: COGS | C35: =C31*C34 -> 192841.09 | D35: =D31*D34 -> 190583.64 | E35: =E31*E34 -> 193121.29 | F35: =F31*F34 -> 190461.68 | G35: =G31*G34 -> 192905.93 | H35: =H31*H34 -> 245085.09 | I35: =I31*I34 -> 247445.29 | J35: =J31*J34 -> 244549.34 | ... N35: =N31*N34 -> 243572.88
B37: Other income / (expense), net % of COGS | C37: 0.025 | D37: 0.025 | E37: 0.025 | F37: 0.025 | G37: 0.025 | H37: 0.025 | I37: 0.025 | J37: 0.025 | K37: 0.025 | L37: 0.025 | M37: 0.025 | N37: 0.025
B38: Other income / (expense), net | C38: =C37*C35 -> 4821.0272 | D38: =D37*D35 -> 4764.591 | E38: =E37*E35 -> 4828.0323 | F38: =F37*F35 -> 4761.542 | G38: =G37*G35 -> 4822.6482 | H38: =H37*H35 -> 6127.1272 | I38: =I37*I35 -> 6186.1323 | J38: =J37*J35 -> 6113.7336 | ... N38: =N37*N35 -> 6089.322
A40: x | B40: Tax Rate | C40: 0.25

Sheet Sheet3

Sheet Purchase Order(PO)
A1: PO Number | B1: PO Date | C1: Department | D1: Vendor | E1: Category | F1: Amount | G1: Actual Spend | H1: Status | I1: Payment Date | J1: Budget | K1: Variance | L1: Variance% | M1: Budget Status
A2: PO1001 | B2: 2025-01-03 | C2: Marketing | D2: Google Ads | E2: Advertising | F2: 45000 | G2: 45000 | H2: Paid | I2: 2025-01-20 | J2: 50000 | K2: =J2-G2 -> 5000 | L2: =K2/J2 -> 0.1 | M2: =IF(G2>J2,"Over Budget","Within Budget") -> Within Budget
A3: PO1002 | B3: 2025-01-05 | C3: Marketing | D3: Meta Ads | E3: Advertising | F3: 38000 | G3: 38000 | H3: Paid | I3: 2025-01-22 | J3: 50000 | K3: =J3-G3 -> 12000 | L3: =K3/J3 -> 0.24 | M3: =IF(G3>J3,"Over Budget","Within Budget") -> Within Budget
A4: PO1003 | B4: 2025-01-06 | C4: HR | D4: ABC Recruiters | E4: Recruitment | F4: 25000 | G4: 25000 | H4: Paid | I4: 2025-01-25 | J4: 30000 | K4: =J4-G4 -> 5000 | L4: =K4/J4 -> 0.16666667 | M4: =IF(G4>J4,"Over Budget","Within Budget") -> Within Budget
A5: PO1004 | B5: 2025-01-08 | C5: Engineering | D5: Dell | E5: Hardware | F5: 85000 | G5: 85000 | H5: Paid | I5: 2025-01-28 | J5: 100000 | K5: =J5-G5 -> 15000 | L5: =K5/J5 -> 0.15 | M5: =IF(G5>J5,"Over Budget","Within Budget") -> Within Budget
A6: PO1005 | B6: 2025-01-10 | C6: Support | D6: Freshdesk | E6: Software | F6: 32000 | G6: 32000 | H6: Paid | I6: 2025-01-30 | J6: 40000 | K6: =J6-G6 -> 8000 | L6: =K6/J6 -> 0.2 | M6: =IF(G6>J6,"Over Budget","Within Budget") -> Within Budget
A7: PO1006 | B7: 2025-02-03 | C7: Marketing | D7: Google Ads | E7: Advertising | F7: 47000 | G7: 47000 | H7: Paid | I7: 2025-02-18 | J7: 50000 | K7: =J7-G7 -> 3000 | L7: =K7/J7 -> 0.06 | M7: =IF(G7>J7,"Over Budget","Within Budget") -> Within Budget
A8: PO1007 | B8: 2025-02-05 | C8: HR | D8: LinkedIn | E8: Recruitment | F8: 28000 | G8: 28000 | H8: Paid | I8: 2025-02-20 | J8: 30000 | K8: =J8-G8 -> 2000 | L8: =K8/J8 -> 0.066666667 | M8: =IF(G8>J8,"Over Budget","Within Budget") -> Within Budget
A9: PO1008 | B9: 2025-02-06 | C9: Engineering | D9: AWS | E9: Cloud Services | F9: 92000 | G9: 92000 | H9: Paid | I9: 2025-02-22 | J9: 100000 | K9: =J9-G9 -> 8000 | L9: =K9/J9 -> 0.08 | M9: =IF(G9>J9,"Over Budget","Within Budget") -> Within Budget
A10: PO1009 | B10: 2025-02-09 | C10: Finance | D10: KPMG | E10: Consulting | F10: 55000 | G10: 55000 | H10: Paid | I10: 2025-02-25 | J10: 60000 | K10: =J10-G10 -> 5000 | L10: =K10/J10 -> 0.083333333 | M10: =IF(G10>J10,"Over Budget","Within Budget") -> Within Budget
A11: PO1010 | B11: 2025-02-12 | C11: Support | D11: Zoho | E11: Software | F11: 21000 | G11: 21000 | H11: Paid | I11: 2025-02-28 | J11: 40000 | K11: =J11-G11 -> 19000 | L11: =K11/J11 -> 0.475 | M11: =IF(G11>J11,"Over Budget","Within Budget") -> Within Budget
A12: PO1011 | B12: 2025-03-02 | C12: Marketing | D12: Meta Ads | E12: Advertising | F12: 44000 | G12: 44000 | H12: Paid | I12: 2025-03-19 | J12: 50000 | K12: =J12-G12 -> 6000 | L12: =K12/J12 -> 0.12 | M12: =IF(G12>J12,"Over Budget","Within Budget") -> Within Budget
A13: PO1012 | B13: 2025-03-04 | C13: Engineering | D13: Dell | E13: Hardware | F13: 78000 | G13: 78000 | H13: Paid | I13: 2025-03-21 | J13: 100000 | K13: =J13-G13 -> 22000 | L13: =K13/J13 -> 0.22 | M13: =IF(G13>J13,"Over Budget","Within Budget") -> Within Budget
... A21: PO1020 | B21: 2025-04-12 | C21: Finance | D21: KPMG | E21: Consulting | F21: 61000 | G21: 61000 | H21: Paid | I21: 2025-04-28 | J21: 60000 | K21: =J21-G21 -> -1000 | L21: =K21/J21 -> -0.016666667 | M21: =IF(G21>J21,"Over Budget","Within Budget") -> Over Budget

Sheet Dashboard
A2: Total Budget | B2: =SUM('Purchase Order(PO)'!J:J) -> 1110000 | F2: Row Labels | G2: Sum of Actual Spend
A3: Total Actual Spend | B3: =SUM('Purchase Order(PO)'!G:G) -> 957000 | F3: Engineering | G3: 351000
A4: Total Variance | B4: =SUM('Purchase Order(PO)'!K:K) -> 153000 | F4: Finance | G4: 165000
A5: Total POs | B5: =COUNTA('Purchase Order(PO)'!A:A)-1 -> 20 | F5: HR | G5: 108000
A6: Over Budget POs | B6: =COUNTIF('Purchase Order(PO)'!M:M,"Over Budget") -> 2 | F6: Marketing | G6: 225000
F7: Support | G7: 108000
F8: Grand Total | G8: 957000
A11: Row Labels | B11: Sum of Budget | C11: Sum of Actual Spend | J11: Row Labels | K11: Count of PO Number
A12: Engineering | B12: 400000 | C12: 351000 | J12: Paid | K12: 20
A13: Finance | B13: 180000 | C13: 165000 | J13: Grand Total | K13: 20
A14: HR | B14: 120000 | C14: 108000
A15: Marketing | B15: 250000 | C15: 225000
A16: Support | B16: 160000 | C16: 108000
A17: Grand Total | B17: 1110000 | C17: 957000

Sheet Visuals
B2: in USD | C2: ='Income Statement'!C5 -> 45658 | D2: =EDATE(C2,1) -> 45689 | E2: =EDATE(D2,1) -> 45717 | F2: =EDATE(E2,1) -> 45748 | G2: =EDATE(F2,1) -> 45778 | H2: =EDATE(G2,1) -> 45809 | I2: =EDATE(H2,1) -> 45839 | J2: =EDATE(I2,1) -> 45870 | K2: =EDATE(J2,1) -> 45901 | ... N2: =EDATE(M2,1) -> 45992
B3: Revenue | C3: ='Income Statement'!C6 -> 642803.63 | D3: ='Income Statement'!D6 -> 635278.8 | E3: ='Income Statement'!E6 -> 643737.63 | F3: ='Income Statement'!F6 -> 634872.27 | G3: ='Income Statement'!G6 -> 643019.76 | H3: ='Income Statement'!H6 -> 816950.3 | I3: ='Income Statement'!I6 -> 824817.63 | J3: ='Income Statement'!J6 -> 815164.47 | ... N3: ='Income Statement'!N6 -> 811909.59
B4: Profit Margin | C4: ='Income Statement'!C22/Visuals!C3 -> 0.15673099 | D4: ='Income Statement'!D22/Visuals!D3 -> 0.15328786 | E4: ='Income Statement'!E22/Visuals!E3 -> 0.15507296 | F4: ='Income Statement'!F22/Visuals!F3 -> 0.1513318 | G4: ='Income Statement'!G22/Visuals!G3 -> 0.15327074 | H4: ='Income Statement'!H22/Visuals!H3 -> 0.23239305 | I4: ='Income Statement'!I22/Visuals!I3 -> 0.23282074 | J4: ='Income Statement'!J22/Visuals!J3 -> 0.23015517 | ... N4: ='Income Statement'!N22/Visuals!N3 -> 0.22692186
